Workbook

Sheet 🤝 Client information
C11: Project scope & Set-up
N13: Contract status
C17: 1 Introduction
A18: <<< unfold +
C22: Purpose
C23: This document serves the purpose to align the project team of the client with the different internal teams at Skipr.
C25: Document set-up
C26: Please complete the tabs Client information, Mobility Program(s) to the best of your ability and at your earliest convenience.
C27: Please avoid changing the layout of this excel, as it might impact underlying formulas.
C28: Some sections might be folded, please use the '+' icon in the nav bar, next to the indication " <<< unfold + " to unfold them.
C30: Process
C31: The dedicated CSM at Skipr shares this document with the client, the client thereafter completes tabs Client information and Mobility Program(s) to the best of their ability.
C32: The tab GO LIVE planning will be completed together with the CSM.
C33: Upon completion of tab client information and Mobility Program(s), the client shares the completed excel file back to the dedicated CSM.
C34: A meeting is scheduled to review the information together.
C36: Based on the provided information, a go live planning is shaped (draft).
... C41: Thank you for taking the time to complete this questionnaire! 😊
B45: 🎯 | C45: 2 Objectives
A46: <<< unfold +
C50: 2.1 Please copy-paste your 3 main strategic business objectives
C52: Startegic Business Objectives (copy)
C53: Ensure compliance with legislastion
C54: Reduce cost linked to mobility
C55: Centralise mobility data
C56: Measure CO2 emissions | G56: My selection of 3 business objectives (paste)
C57: Attract new talent on the job market
C58: Increase available mobility options | F58: >>>
C59: Reduce workload linked to mobility
C60: Increase employee retention
C61: Provide insights to executive team
C62: Reduce car fleet
C64: 2.2 Please define at least one metric to measure the success of this project
C65: (example: X starters in the mobility program at the launch of the project)
B71: 🏢 | C71: 3 Company profile information
A72: <<< unfold +
C76: 3.1 Please complete the company information table below *
C77: Layout note: adding rows to this table is allowed (if needed) but please ensure the total # of employees sum is correct | M77: (Invoices are also send via Peppol)
C78: Name of entity * | F78: Parent entity | G78: VAT number * | H78: Street + nr. * | K78: Postal code, city * | L78: # of employees * | M78: Skipr fee invoice recipient e-mail address * | O78: PO number
B80: Mother entity =
B81: (if applicable)
...

Sheet 🚀 Mobility program(s)
C12: 🚀 | E12: Mobility program configuration
E17: Introduction mobility program configuration
E21: Please complete all grey fields to the best of your ability at your earliest convenience.
E22: Please do not change the layout of this template, as it might impact underlying formulas.
E23: Some sections might be folded, please use the '+' icon in the nav bar, next to the indication " <<< unfold + " to unfold them.
E24: Some grey fields might be dropdown menus, please select the cell and (if applicable) select one of the dropdown options.
E25: There is a section provided at the right to ask questions / leave comments in case of doubt ("Additional comments of client").
E26: In case you will start with multiple mobility programs, please complete one mobility program configuration per program.
E29: Thank you for taking the time to complete this questionnaire 😊
E35: Mobility program configuration (1)
P37: Additional comments of client | S37: Additional comments of Skipr
A38: <<< unfold + | E38: 1. Choose a name for the mobility program
E39: Mobility program template | J39: Please select a template >>>
E40: A default list of allowed mobilty services is proposed based on the selected mobility program template above, please customise it in column M
A41: <<< unfold + | E41: 2. Allowed mobility services | L41: Default | M41: Customise
E42: B-parking | L42: =IF(OR(L39="Federal Mobility Budget", L39="Commute", L39="professional travel"), "Yes", IF(L39="EV Charging & Fuel", "No", "")) | M42: =L42
E43: Bike leasing | L43: =IF(L39="Commute","Often",IF(L39="Federal Mobility Budget","Often",IF(OR(L39="Professional Travel",L39="EV Charging & Fuel"),"No",L39)))
E44: Bike purchase & Accessories | L44: =IF(OR(L39="Federal Mobility Budget"), "Yes", IF(OR(L39="professional travel", L39="EV Charging & Fuel", L39="Commute"), "No", "")) | M44: =L44
E45: Bike rent | L45: =IF(L39="Commute","Often",IF(L39="Federal Mobility Budget","Yes",IF(OR(L39="EV Charging & Fuel",L39="professional travel"),"No","")))
E46: Bus | L46: =IF(OR(L39="Federal Mobility Budget"), "Yes", IF(OR(L39="professional travel", L39="EV Charging & Fuel", L39="Commute"), "No", "")) | M46: =L46
E47: Car leasing (pillar 1) | L47: =IF(OR(L39="Federal Mobility Budget"), "Often", IF(OR(L39="professional travel", L39="EV Charging & Fuel", L39="Commute"), "No", ""))
E48: Car rental | L48: =IF(OR(L39="Federal Mobility Budget"), "Yes", IF(OR(L39="professional travel", L39="EV Charging & Fuel", L39="Commute"), "No", "")) | M48: =L48
E49: Car sharing | L49: =IF(OR(L39="Federal Mobility Budget", L39="professional travel"), "Yes", IF(OR(L39="EV Charging & Fuel", L39="Commute"), "No", "")) | M49: =L49
E50: Carpooling | L50: =IF(OR(L39="Federal Mobility Budget"), "Yes", IF(OR(L39="professional travel", L39="EV Charging & Fuel", L39="Commute"), "No", "")) | M50: =L50
E51: Shared bike | L51: =IF(OR(L39="Federal Mobility Budget", L39="Commute", L39="professional travel"), "Yes", IF(L39="EV Charging & Fuel", "No", "")) | M51: =L51
E52: Kickscooter | L52: =IF(OR(L39="Federal Mobility Budget", L39="Commute", L39="professional travel"), "Yes", IF(L39="EV Charging & Fuel", "No", "")) | M52: =L52
E53: Scooter | L53: =IF(OR(L39="Federal Mobility Budget"), "Yes", IF(OR(L39="professional travel", L39="EV Charging & Fuel", L39="Commute"), "No", "")) | M53: =L53
E54: Public parking | L54: =IF(OR(L39="professional travel"), "Yes", IF(OR(L39="Federal Mobility Budget", L39="EV Charging & Fuel", L39="Commute"), "No", "")) | M54: =L54
E55: Public transport tickets | L55: =IF(OR(L39="Federal Mobility Budget", L39="Commute", L39="professional travel"), "Yes", IF(L39="EV Charging & Fuel", "No", "")) | M55: =L55
E56: Public transport subscriptions | L56: =IF(OR(L39="Federal Mobility Budget", L39="Commute", L39="professional travel"), "Yes", IF(L39="EV Charging & Fuel", "No", "")) | M56: =L56
E57: Taxi | L57: =IF(OR(L39="Federal Mobility Budget", L39="professional travel"), "Yes", IF(OR(L39="EV Charging & Fuel", L39="Commute"), "No", "")) | M57: =L57
E58: Fuel stations | L58: =IF(OR(L39="Federal Mobility Budget", L39="Commute", L39="professional travel"), "No", IF(L39="EV Charging & Fuel", "Yes", "")) | M58: =L58
E59: Toll | L59: =IF(OR(L39="Federal Mobility Budget", L39="Commute", L39="professional travel"), "No", IF(L39="EV Charging & Fuel", "No", "")) | M59: =L59
E60: Housing cost | L60: =IF(OR(L39="Federal Mobility Budget"), "Yes", IF(OR(L39="professional travel", L39="EV Charging & Fuel", L39="Commute"), "No", "")) | M60: =L60
E61: If the employee lives within a radius of 10km from the usual place of work | K61: =IF((L60="Yes"),"Yes allow","")
E62: If the employee works more than 50% from home | K62: =IF((L60="Yes"),"Yes allow","")
E63: Bike allowance (click on '+' next to row 60 to configure) | L63: =IF(OR(L39="Federal Mobility Budget", L39="Commute", L39="professional travel"), "Yes", IF(L39="EV Charging & Fuel", "No", "")) | M63: =L63
E64: €/km | K64: =IF(OR(L63="Yes",L63="Often"),"0.37","") | M64: =K64
E65: Max km/ journey | K65: =IF(OR(L63="Yes",L63="Often"),"120","") | M65: =K65
E66: Allow employee to manually adapt the automatically proposed distance? | K66: =IF(OR(L63="Yes",L63="Often"),"No don't allow","")
...

Sheet 📢 GO LIVE planning
C12: 📢 | D12: Communication plan
D17: Introduction communication plan
D18: In order to guarantee a successful launch of the mobility budget within your company, a well-throughout communication plan is needed.
D19: Implementing a new mobility policy and introducing a new mobility tool comes with it's complexity, but if you follow the ADKAR model, it becomes easy!
D23: ADKAR model, what's that?
D24: During the implementation phase, there are different stakeholders that need to receive information.
D25: The ADKAR model ensures the right people receive the right information at the right time.
D27: ADKAR stands for Awareness, Desire, Knowledge, Ability, Reinforcement.
D28: Based on the information you provided in the tab "Mobility Program", we can now start building your communication plan.
D30: Please find hereunder a communication plan proposal, based on your GO LIVE date.
D31: This is a draft, dates might fall in the weekend and will have to be rescheduled.
B34: Your tailor-made communication plan
B38: 🎯 | C38: Mobility Program | F38: ='🚀 Mobility program(s)'!I38
C39: GO LIVE date | F39: ='🚀 Mobility program(s)'!M109
B42: Awareness | F42: Desire | J42: Knowledge & Ability | N42: Reinforcement
B43: Once you know what you want to offer to your employees and your mobility policy draft is getting finalized, we can start the communication towards your employees. This is the awareness phase. Skipr creates a custom slidedeck based on your policy and takes care of the communication during an online info session. This session can be recorded for later purposes, it is therefore important that the meeting invites are sent out by the client (not by Skipr) so the recording automatically arrives in the mailbox of the client after the meeting has ended. | F43: After the info session, your employees are well-informed about the mobility policy / legislation / employee benefit. In case the benefit is the Mobility Budget, this is the phase eligible employees have the time to inform HR about their interest to join the FMB (at the end of their current lease). The mobility budget amount is communicated to them individually and a contract addendum is shared (and signed) with those who can opt in. It is recommended to keep a list of interested employees, so they remain on your radar. | J43: During this phase, Skipr ensures all stakeholders are well-informed on the processes that come with the tool. Admins receive an admin training one week before the GO LIVE Employees receive an employee user training on the day they start receiving the benefit => this marks the GO LIVE date These sessions can be recorded for later purposes, it is therefore important that these sessions are sent out by the client (not by Skipr) so the recording automatically arrives in the mailbox of the client after the meeting has ended. | N43: To ensure your employees and your admins receive the best support, please make sure to share the following documents and hyperlinks with your company.
F54: Communication Package available upon request | J54: ADMIN TRAINING (meeting) | M54: =M59-7 -> -7 | N54: Info session slidedeck
B55: Info session: | N55: Info session recording
B56: 1) Slidedeck ready | E56: =E57-14 -> -58 | F56: Onepagers | J56: User training: | N56: User guide
B57: 2) Meeting invite sent out | E57: =E58-14 -> -44 | F57: Email templates | J57: 1) Slidedeck ready | M57: =M59-14 -> -14 | N57: User training recording
B58: 3) INFO SESSION (meeting) | E58: =F39-30 -> -30 | F58: user guides | J58: 2) Meeting invite sent out | M58: =M59-14 -> -14 | N58: Your dedicated CSM contact | P58: ='🤝 Client information'!F130
F59: Informative videos | J59: 3) USER TRAINING (meeting) | M59: =F39 | N59: Dashboard URL | P59: https://move.ayvens.com/
B60: Slidedeck shared with employees | E60: =E57 -> -44 | F60: etc. | N60: FAQ pages employees | P60: https://aldmove.zendesk.com/hc/en-us/categories/20561192896018-Employee
B61: Recording of info session available on intranet | E61: =E60+2 -> -42 | J61: Slidedeck shared with employees | M61: =F39 | N61: FAQ pages admins | P61: https://aldmove.zendesk.com/hc/en-us/categories/20561171188242-Admin
J62: Recording of user training available on intranet | M62: =F39+2 -> 2 | N62: Direct support | P62: https://aldmove.zendesk.com/hc/nl-be/requests/new
B64: +/- 1 to 2 months prior to GO LIVE | F64: Duration = +/- 3 weeks | J64: GO LIVE | N64: Hypercare phase

Sheet ✅ KYC documents
B12: ✅ | D12: KYC status check
D16: KYC : What? (Click on '+' to unfold and read more)
A17: <<< unfold +
D19: KYC stands for “Know Your Customer” and refers to the regulatory procedures that banks and other regulated institutions must follow.
D20: Under European and national legislation, the process verifies the identity of a customer (legal or natural person)
D21: by reviewing official documents such as an ID card, passport, proof of address, or company documents (e.g. articles of association, Kbis).
D23: As Skipr acts as a commercial agent for Treezor (the financial institution that opens payment accounts for our clients),
D24: we must demonstrate that we are in direct contact with the client requesting the account (payment account for mobility expenses)
D25: This is done by providing specific documents, as explained below.
D27: KYC : Why? (Click on '+' to unfold and read more)
A28: <<< unfold +
D30: 1. Creation of a payment account (company wallet)
D31: To allow employees to make mobility purchases, a payment account must first be created to which their mobility payment card will be linked.
D33: 2. One company wallet per entity
D34: For accounting purposes, we create one company wallet per entity using our solution. Employees are then linked to their respective entity in the platform.
D36: 3. The mobility payment card
D37: Each employee receives a mobility payment card (debit Mastercard) linked to their entity’s company wallet.
D38: The card can only be used for mobility expenses that comply with your company mobility policy.
D40: 4. KYC verification
D41: To comply with EU anti-money laundering legislation, we must complete a KYC process with our financial partner Treezor.
D42: This requires identifying the company’s ultimate beneficiary or legal representative(s) and providing identification (ID card or passport)
D43: and other documents to confirm our relationship with the client.
D47: Please collect the below documents and share them with your CSM at Skipr
D50: Your KYC tracker 👉 A tool to help you collect the KYC documents
D53: Name of entity | N53: Additional comments of client
A54: <<< unfold + | D54: ='🤝 Client information'!C80 | J54: Goal Tracker | K54: =IFERROR( ( IF(K55="Shared with Skipr",1,IF(OR(K55="Got it (not shared yet)",K55="transfer confirmation received"),0.75,IF(OR(K55="Collecting",K55="3. info shared with finance colleague"),0.25,0))) +IF(K56="Shared with Skipr",1,IF(OR(K56="Got it (not shared yet)",K56="transfer confirmation received"),0.75,IF(OR(K56="Collecting",K56="3. info shared with finance colleague"),0.25,0))) +IF(K58="Shared with Skipr",1,IF(OR(K58="Got it (not shared yet)",K58="transfer confirmation received"),0.75,IF(OR(K58="Collecting",K58="3. info shared with finance colleague"),0.25,0))) +IF(K60="Shared with Skipr",1,IF(OR(K60="Got it (not shared yet)",K60="transfer confirmation received"),0.75,IF(OR(K60="Collecting",K60="3. info shared with finance colleague"),0.25,0))) +IF(K62="Shared with Skipr",1,IF(OR(K62="Got it (not shared yet)",K62="transfer confirmation received"),0.75,IF(OR(K62="Collecting",K62="3. info shared with finance colleague"),0.25,0))) +IF(K64="Shared with Skipr",1,IF(OR(K64="Got it (not shared yet)",K64="transfer confirmation received"),0.75,IF(OR(K64="Collecting",K64="3. info shared with finance colleague"),0.25,0))) +IF(K66="Shared with Skipr",1,IF(OR(K66="Got it (not shared yet)",K66="transfer confirmation received"),0.75,IF(OR(K66="Collecting",K66="3. info shared with finance colleague"),0.25,0))) +IF(K68="Shared with Skipr",1,IF(OR(K68="Got it (not shared yet)",K68="transfer confirmation received"),0.75,IF(OR(K68="Collecting",K68="3. info shared with finance colleague"),0.25,0))) +IF(K70="Shared with Skipr",1,IF(OR(K70="Got it (not shared yet)",K70="transfer confirmation received"),0.75,IF(OR(K70="Collecting",K70="info shared with finance colleague"),0.25,0))) +IF(K71="Shared with Skipr",1,IF(OR(K71="Got it (not shared yet)",K71="transfer confirmation received"),0.75,IF(OR(K71="Collecting",K71="3. info shared with finance colleague"),0.25,0))) +IF(K76="Shared with Skipr",1,IF(OR(K76="Got it (not shared yet)",K76="transfer confirmation received"),0.75,IF(OR(K76="Collecting",K76="3. info shared with finance colleague"),0.25,0))) +IF(K81="5. Skipr informed of Transfer",1,IF(OR(K81="Got it (not shared yet)",K81="transfer confirmation received"),0.75,IF(OR(K81="Collecting",K81="3. info shared with finance colleague"),0.25,0))) ) / ( COUNTIF(K55,"<>N/A")+COUNTIF(K56,"<>N/A")+COUNTIF(K58,"<>N/A")+COUNTIF(K60,"<>N/A")+COUNTIF(K62,"<>N/A")+COUNTIF(K64,"<>N/A")+COUNTIF(K66,"<>N/A")+COUNTIF(K68,"<>N/A")+COUNTIF(K70,"<>N/A")+COUNTIF(K71,"<>N/A")+COUNTIF(K76,"<>N/A")+COUNTIF(K81,"<>N/A") ) ,0) -> 0.22916667
D55: - Constitution document | K55: Shared with Skipr
D56: - KBO document (less than 3 months old) | K56: Got it (not shared yet)
D57: 💡 Please download KBO via this URL: https://kbopub.economie.fgov.be/kbopub/zoeknummerform.html?lang=nl
D58: - Annual report J-1 | K58: Shared with Skipr
D59: 💡 Scroll down on the KBO document to find the hyperlinks to the annual report J-1
D60: - Signed Statuts | K60: not started
D61: 💡 Please download via this URL: https://statuts.notaire.be/stapor_v1/search
D62: - UBO register (less than 3 months old) | K62: not started
E63: 1) Is your company owned by a listed company?
E64: 1.1) If yes, please provide a proof that the parent entity is listed. | K64: not started
D65: 💡 | E65: Proof can be a screenshot of the Google search result : "Stock Price (PARENT ENTITY NAME)"
E66: 1.2) If no, please provide the UBO of the parent entity. | K66: not started
E67: 2) Is your company (partially) owned by a non-listed company?
E68: 2.1) If yes, please provide the UBO of that company | K68: not started
...

Sheet 📚 CSM overview
A2: 📚 | B2: Planhat information
A5: 💡 | B5: Attention points (to be completed by CSM): | E5: Please complete the open field below
A10: 🎛️ | B10: General client info
B11: Actionable objectives | F11: ='🤝 Client information'!G57 | I11: ='🤝 Client information'!G58 | L11: ='🤝 Client information'!G59
B12: Main SPOC | F12: ='🤝 Client information'!F95 | I12: ='🤝 Client information'!H95
D13: Contact Skipr | F13: ='🤝 Client information'!F130 | I13: ='🤝 Client information'!H130 -> Customer Success Manager
B14: Total number of employees (all entities) | F14: ='🤝 Client information'!L90 -> 0
B15: Total number of company cars (all entities) | F15: ='🤝 Client information'!F171 -> 0
D16: Total estimated number of employees at start | F16: =F37+I37+L37+O37+R37 -> 0
D17: Phyiscal cards | F17: ='🤝 Client information'!O206
B18: Smartelia Expense validation | F18: ='🤝 Client information'!O185 | G18: ='🤝 Client information'!J194 -> teambackoffice.skipr+...@smartelia.com
B19: SSO | F19: ='🤝 Client information'!O195
B20: User data management | F20: ='🤝 Client information'!O196 | G20: =IF(ISBLANK(F20),"","Keep in mind manual changes are overruled by the User Data Management")
B21: Custom Payroll Report | F21: ='🤝 Client information'!O197
B22: Payroll cut-off day | F22: ='🤝 Client information'!O199
B23: Payroll Delivery day | F23: ='🤝 Client information'!O200
D24: Pillar 3 payout company leavers | F24: ='🤝 Client information'!O201
B25: PTO management | F25: ='🤝 Client information'!O204
A27: 💸 | B27: Finance | F27: (Parent, if applicable)
B28: Parent + daughter entities | F28: ='🤝 Client information'!C80 | I28: ='🤝 Client information'!C81 | L28: ='🤝 Client information'!C82 | O28: ='🤝 Client information'!C83 | R28: ='🤝 Client information'!C84 | U28: ='🤝 Client information'!C85 | X28: ='🤝 Client information'!C86 | AA28: ='🤝 Client information'!C87 | AD28: ='🤝 Client information'!C88 | AG28: ='🤝 Client information'!$C89
B29: Invoicing recipient | F29: ='🤝 Client information'!M80 | I29: ='🤝 Client information'!M81 | L29: ='🤝 Client information'!M82 | O29: ='🤝 Client information'!M83 | R29: ='🤝 Client information'!M84 | U29: ='🤝 Client information'!M85 | X29: ='🤝 Client information'!M86 | AA29: ='🤝 Client information'!M87 | AD29: ='🤝 Client information'!M88 | AG29: ='🤝 Client information'!M89
B30: PO number | F30: ='🤝 Client information'!O80 | I30: ='🤝 Client information'!O81 | L30: ='🤝 Client information'!O82 | O30: ='🤝 Client information'!O83 | R30: ='🤝 Client information'!O84 | U30: ='🤝 Client information'!O85 | X30: ='🤝 Client information'!O86 | AA30: ='🤝 Client information'!O87 | AD30: ='🤝 Client information'!O88 | AG30: ='🤝 Client information'!O89
A32: 🚀 | B32: Mobility programs sum-up | F32: =IF(ISBLANK(F34),"","(1)") | I32: =IF(ISBLANK(I34),"","(2)") | L32: =IF(ISBLANK(L34),"","(3)") | O32: =IF(ISBLANK(O34),"","(4)") | R32: =IF(ISBLANK(R34),"","(5)")
B33: Mobility programs (default) | F33: ='🚀 Mobility program(s)'!L39 | I33: ='🚀 Mobility program(s)'!L133 | L33: ='🚀 Mobility program(s)'!L227 | O33: ='🚀 Mobility program(s)'!L321 | R33: ='🚀 Mobility program(s)'!L415
B34: Mobility Program custom name | F34: ='🚀 Mobility program(s)'!I38 | I34: ='🚀 Mobility program(s)'!I132 | L34: ='🚀 Mobility program(s)'!I226 | O34: ='🚀 Mobility program(s)'!I320 | R34: ='🚀 Mobility program(s)'!I414
B35: Requested GO LIVE | F35: ='🚀 Mobility program(s)'!M109 | G35: =IF(ISBLANK(F34),"","Go live") | I35: ='🚀 Mobility program(s)'!M203 | J35: =IF(ISBLANK(I34),"","Go live") | L35: ='🚀 Mobility program(s)'!M297 | M35: =IF(ISBLANK(L34),"","Go live") | O35: ='🚀 Mobility program(s)'!M391 | P35: =IF(ISBLANK(O34),"","Go live") | R35: ='🚀 Mobility program(s)'!M485 | S35: =IF(ISBLANK(R34),"","Go live")
B36: Eligible employees | F36: ='🚀 Mobility program(s)'!M107 | G36: =IF(ISBLANK(F34),"","eligible") | I36: ='🚀 Mobility program(s)'!M201 | J36: =IF(ISBLANK(I34),"","eligible") | L36: ='🚀 Mobility program(s)'!M295 | M36: =IF(ISBLANK(L34),"","eligible") | O36: ='🚀 Mobility program(s)'!M389 | P36: =IF(ISBLANK(O34),"","eligible") | R36: ='🚀 Mobility program(s)'!M483 | S36: =IF(ISBLANK(R34),"","eligible")
B37: Expected users at start | F37: ='🚀 Mobility program(s)'!M108 | G37: =IF(ISBLANK(F34),"","expected") | I37: ='🚀 Mobility program(s)'!M202 | J37: =IF(ISBLANK(I34),"","expected") | L37: ='🚀 Mobility program(s)'!M296 | M37: =IF(ISBLANK(L34),"","expected") | O37: ='🚀 Mobility program(s)'!M390 | P37: =IF(ISBLANK(O34),"","expected") | R37: ='🚀 Mobility program(s)'!M484 | S37: =IF(ISBLANK(R34),"","expected")
B38: Number of (mobility) services | F38: =IF(COUNTIF('🚀 Mobility program(s)'!M42:M82, "yes")>0,COUNTIF('🚀 Mobility program(s)'!M42:M82, "yes"),"") | G38: =IF(ISBLANK(F34),"","services") | I38: =IF(COUNTIF('🚀 Mobility program(s)'!M136:M176, "yes")>0,COUNTIF('🚀 Mobility program(s)'!M136:M176, "yes"),"") | J38: =IF(ISBLANK(I34),"","services") | L38: =IF(COUNTIF('🚀 Mobility program(s)'!M230:M270, "yes")>0,COUNTIF('🚀 Mobility program(s)'!M230:M270, "yes"),"") | M38: =IF(ISBLANK(L34),"","services") | O38: =IF(COUNTIF('🚀 Mobility program(s)'!M324:M364, "yes")>0,COUNTIF('🚀 Mobility program(s)'!M324:M364, "yes"),"") | P38: =IF(ISBLANK(O34),"","services") | R38: =IF(COUNTIF('🚀 Mobility program(s)'!M418:M458, "yes")>0,COUNTIF('🚀 Mobility program(s)'!M418:M458, "yes"),"") | S38: =IF(ISBLANK(R34),"","services")
B39: Number of groups | F39: =IF(COUNTA('🚀 Mobility program(s)'!E97:E104)=0, 1, COUNTA('🚀 Mobility program(s)'!E97:E104)) -> 1 | G39: =IF(ISBLANK(F34),"","groups") | I39: =IF(COUNTA('🚀 Mobility program(s)'!E191:E198)=0, 1, COUNTA('🚀 Mobility program(s)'!E191:E198)) -> 1 | J39: =IF(ISBLANK(I34),"","groups") | L39: =IF(COUNTA('🚀 Mobility program(s)'!E285:E292)=0, 1, COUNTA('🚀 Mobility program(s)'!E285:E292)) -> 1 | M39: =IF(ISBLANK(L34),"","groups") | O39: =IF(COUNTA('🚀 Mobility program(s)'!E379:E384)=0, 1, COUNTA('🚀 Mobility program(s)'!E379:E384)) -> 1 | P39: =IF(ISBLANK(O34),"","groups") | R39: =IF(COUNTA('🚀 Mobility program(s)'!E473:E480)=0, 1, COUNTA('🚀 Mobility program(s)'!E473:E480)) -> 1 | S39: =IF(ISBLANK(R34),"","groups")
B40: Geographical scope | G40: ='🚀 Mobility program(s)'!M106 | J40: ='🚀 Mobility program(s)'!M200 | M40: ='🚀 Mobility program(s)'!M294 | P40: ='🚀 Mobility program(s)'!M388 | S40: ='🚀 Mobility program(s)'!M482
B41: Reimbursement requests allowed? | G41: ='🚀 Mobility program(s)'!M112 | J41: ='🚀 Mobility program(s)'!M206 | M41: ='🚀 Mobility program(s)'!M300 | P41: ='🚀 Mobility program(s)'!M394 | S41: ='🚀 Mobility program(s)'!M488
B42: Reimbursement additional comments | F42: ='🚀 Mobility program(s)'!E115 | I42: ='🚀 Mobility program(s)'!E209 | L42: ='🚀 Mobility program(s)'!E303 | O42: ='🚀 Mobility program(s)'!E397 | R42: ='🚀 Mobility program(s)'!E491

Sheet ✍️ CSM notes
C11: ✍️ CSM notes
C15: Please write down all client specificities that might be useful for the AI agents to know.
C16: What is important to the client? Where do they deviate from the default behaviour of clients?
A18: < Read more | B18: =IF(ISBLANK(C18), "", IF(B18="", NOW(), IF(C18<>C18, NOW(), B18)))
A35: < Read more | B35: =IF(ISBLANK(C35), "", IF(B35="", NOW(), IF(C35<>C35, NOW(), B35)))
A52: < Read more | B52: =IF(ISBLANK(C52), "", IF(B52="", NOW(), IF(C52<>C52, NOW(), B52)))
A69: < Read more | B69: =IF(ISBLANK(C69), "", IF(B69="", NOW(), IF(C69<>C69, NOW(), B69)))
A86: < Read more | B86: =IF(ISBLANK(C86), "", IF(B86="", NOW(), IF(C86<>C86, NOW(), B86)))
A103: < Read more | B103: =IF(ISBLANK(C103), "", IF(B103="", NOW(), IF(C103<>C103, NOW(), B103)))
A120: < Read more | B120: =IF(ISBLANK(C120), "", IF(B120="", NOW(), IF(C120<>C120, NOW(), B120)))
A137: < Read more | B137: =IF(ISBLANK(C137), "", IF(B137="", NOW(), IF(C137<>C137, NOW(), B137)))
A154: < Read more | B154: =IF(ISBLANK(C154), "", IF(B154="", NOW(), IF(C154<>C154, NOW(), B154)))
A171: < Read more | B171: =IF(ISBLANK(C171), "", IF(B171="", NOW(), IF(C171<>C171, NOW(), B171)))
A188: < Read more | B188: =IF(ISBLANK(C188), "", IF(B188="", NOW(), IF(C188<>C188, NOW(), B188)))
A205: < Read more | B205: =IF(ISBLANK(C205), "", IF(B205="", NOW(), IF(C205<>C205, NOW(), B205)))
A222: < Read more | B222: =IF(ISBLANK(C222), "", IF(B222="", NOW(), IF(C222<>C222, NOW(), B222)))

Sheet ☑️  Validations Briefing
A2: ☑️ | B2: Skipr validations briefing
N3: Validations checked by Skipr: | O3: ='🤝 Client information'!O185
D6: Client name | F6: ='🤝 Client information'!C80
F7: First check on | G7: ='🤝 Client information'!O187 | J7: Second check on | K7: ='🤝 Client information'!O188 | N7: Payroll export day | O7: ='🤝 Client information'!O186
D8: Bulk approve recurring expenses? | F8: ='🤝 Client information'!O191
D9: Housing cost: Monthly proof of payment needed? | F9: ='🤝 Client information'!O189
D10: Housing cost: <10km range proof needed? | F10: ='🤝 Client information'!O190
D11: Validations team e-mail | F11: ='🤝 Client information'!J194 -> teambackoffice.skipr+...@smartelia.com
D12: Expected GO LIVE date | F12: ='🚀 Mobility program(s)'!M109
D13: General additional comments | F13: ='🤝 Client information'!E193
F16: 1 | H16: 2 | J16: 3 | L16: 4 | N16: 5
D17: Mobility program(s) | F17: ='🚀 Mobility program(s)'!I38 | H17: ='🚀 Mobility program(s)'!I132 | J17: ='🚀 Mobility program(s)'!I226 | L17: ='🚀 Mobility program(s)'!I320 | N17: ='🚀 Mobility program(s)'!I414
D18: Services | F18: {=IFERROR(INDEX('👾 RAW MAPPING'!$A$19:$A$55, SMALL(IF('👾 RAW MAPPING'!$A$19:$A$55<>"", ROW('👾 RAW MAPPING'!$A$19:$A$55)-ROW('👾 RAW MAPPING'!$A$19)+1), ROW(F18)-ROW(F$18)+1)), "")} | H18: {=IFERROR(INDEX('👾 RAW MAPPING'!$C$19:$C$55, SMALL(IF('👾 RAW MAPPING'!$C$19:$C$55<>"", ROW('👾 RAW MAPPING'!$C$19:$C$55)-ROW('👾 RAW MAPPING'!$C$19)+1), ROW(H18)-ROW(H$18)+1)), "")} | J18: {=IFERROR(INDEX('👾 RAW MAPPING'!$E$19:$E$55, SMALL(IF('👾 RAW MAPPING'!$E$19:$E$55<>"", ROW('👾 RAW MAPPING'!$E$19:$E$55)-ROW('👾 RAW MAPPING'!$E$19)+1), ROW(J18)-ROW(J$18)+1)), "")} | L18: {=IFERROR(INDEX('👾 RAW MAPPING'!$G$19:$G$55, SMALL(IF('👾 RAW MAPPING'!$G$19:$G$55<>"", ROW('👾 RAW MAPPING'!$G$19:$G$55)-ROW('👾 RAW MAPPING'!$G$19)+1), ROW(L18)-ROW(L$18)+1)), "")} | N18: {=IFERROR(INDEX('👾 RAW MAPPING'!$I$19:$I$55, SMALL(IF('👾 RAW MAPPING'!$I$19:$I$55<>"", ROW('👾 RAW MAPPING'!$I$19:$I$55)-ROW('👾 RAW MAPPING'!$I$19)+1), ROW(N18)-ROW(N$18)+1)), "")}
F19: {=IFERROR(INDEX('👾 RAW MAPPING'!$A$19:$A$55, SMALL(IF('👾 RAW MAPPING'!$A$19:$A$55<>"", ROW('👾 RAW MAPPING'!$A$19:$A$55)-ROW('👾 RAW MAPPING'!$A$19)+1), ROW(F19)-ROW(F$18)+1)), "")} | H19: {=IFERROR(INDEX('👾 RAW MAPPING'!$C$19:$C$55, SMALL(IF('👾 RAW MAPPING'!$C$19:$C$55<>"", ROW('👾 RAW MAPPING'!$C$19:$C$55)-ROW('👾 RAW MAPPING'!$C$19)+1), ROW(H19)-ROW(H$18)+1)), "")} | J19: {=IFERROR(INDEX('👾 RAW MAPPING'!$E$19:$E$55, SMALL(IF('👾 RAW MAPPING'!$E$19:$E$55<>"", ROW('👾 RAW MAPPING'!$E$19:$E$55)-ROW('👾 RAW MAPPING'!$E$19)+1), ROW(J19)-ROW(J$18)+1)), "")} | L19: {=IFERROR(INDEX('👾 RAW MAPPING'!$G$19:$G$55, SMALL(IF('👾 RAW MAPPING'!$G$19:$G$55<>"", ROW('👾 RAW MAPPING'!$G$19:$G$55)-ROW('👾 RAW MAPPING'!$G$19)+1), ROW(L19)-ROW(L$18)+1)), "")} | N19: {=IFERROR(INDEX('👾 RAW MAPPING'!$I$19:$I$55, SMALL(IF('👾 RAW MAPPING'!$I$19:$I$55<>"", ROW('👾 RAW MAPPING'!$I$19:$I$55)-ROW('👾 RAW MAPPING'!$I$19)+1), ROW(N19)-ROW(N$18)+1)), "")}
F20: {=IFERROR(INDEX('👾 RAW MAPPING'!$A$19:$A$55, SMALL(IF('👾 RAW MAPPING'!$A$19:$A$55<>"", ROW('👾 RAW MAPPING'!$A$19:$A$55)-ROW('👾 RAW MAPPING'!$A$19)+1), ROW(F20)-ROW(F$18)+1)), "")} | H20: {=IFERROR(INDEX('👾 RAW MAPPING'!$C$19:$C$55, SMALL(IF('👾 RAW MAPPING'!$C$19:$C$55<>"", ROW('👾 RAW MAPPING'!$C$19:$C$55)-ROW('👾 RAW MAPPING'!$C$19)+1), ROW(H20)-ROW(H$18)+1)), "")} | J20: {=IFERROR(INDEX('👾 RAW MAPPING'!$E$19:$E$55, SMALL(IF('👾 RAW MAPPING'!$E$19:$E$55<>"", ROW('👾 RAW MAPPING'!$E$19:$E$55)-ROW('👾 RAW MAPPING'!$E$19)+1), ROW(J20)-ROW(J$18)+1)), "")} | L20: {=IFERROR(INDEX('👾 RAW MAPPING'!$G$19:$G$55, SMALL(IF('👾 RAW MAPPING'!$G$19:$G$55<>"", ROW('👾 RAW MAPPING'!$G$19:$G$55)-ROW('👾 RAW MAPPING'!$G$19)+1), ROW(L20)-ROW(L$18)+1)), "")} | N20: {=IFERROR(INDEX('👾 RAW MAPPING'!$I$19:$I$55, SMALL(IF('👾 RAW MAPPING'!$I$19:$I$55<>"", ROW('👾 RAW MAPPING'!$I$19:$I$55)-ROW('👾 RAW MAPPING'!$I$19)+1), ROW(N20)-ROW(N$18)+1)), "")}
F21: {=IFERROR(INDEX('👾 RAW MAPPING'!$A$19:$A$55, SMALL(IF('👾 RAW MAPPING'!$A$19:$A$55<>"", ROW('👾 RAW MAPPING'!$A$19:$A$55)-ROW('👾 RAW MAPPING'!$A$19)+1), ROW(F21)-ROW(F$18)+1)), "")} | H21: {=IFERROR(INDEX('👾 RAW MAPPING'!$C$19:$C$55, SMALL(IF('👾 RAW MAPPING'!$C$19:$C$55<>"", ROW('👾 RAW MAPPING'!$C$19:$C$55)-ROW('👾 RAW MAPPING'!$C$19)+1), ROW(H21)-ROW(H$18)+1)), "")} | J21: {=IFERROR(INDEX('👾 RAW MAPPING'!$E$19:$E$55, SMALL(IF('👾 RAW MAPPING'!$E$19:$E$55<>"", ROW('👾 RAW MAPPING'!$E$19:$E$55)-ROW('👾 RAW MAPPING'!$E$19)+1), ROW(J21)-ROW(J$18)+1)), "")} | L21: {=IFERROR(INDEX('👾 RAW MAPPING'!$G$19:$G$55, SMALL(IF('👾 RAW MAPPING'!$G$19:$G$55<>"", ROW('👾 RAW MAPPING'!$G$19:$G$55)-ROW('👾 RAW MAPPING'!$G$19)+1), ROW(L21)-ROW(L$18)+1)), "")} | N21: {=IFERROR(INDEX('👾 RAW MAPPING'!$I$19:$I$55, SMALL(IF('👾 RAW MAPPING'!$I$19:$I$55<>"", ROW('👾 RAW MAPPING'!$I$19:$I$55)-ROW('👾 RAW MAPPING'!$I$19)+1), ROW(N21)-ROW(N$18)+1)), "")}
F22: {=IFERROR(INDEX('👾 RAW MAPPING'!$A$19:$A$55, SMALL(IF('👾 RAW MAPPING'!$A$19:$A$55<>"", ROW('👾 RAW MAPPING'!$A$19:$A$55)-ROW('👾 RAW MAPPING'!$A$19)+1), ROW(F22)-ROW(F$18)+1)), "")} | H22: {=IFERROR(INDEX('👾 RAW MAPPING'!$C$19:$C$55, SMALL(IF('👾 RAW MAPPING'!$C$19:$C$55<>"", ROW('👾 RAW MAPPING'!$C$19:$C$55)-ROW('👾 RAW MAPPING'!$C$19)+1), ROW(H22)-ROW(H$18)+1)), "")} | J22: {=IFERROR(INDEX('👾 RAW MAPPING'!$E$19:$E$55, SMALL(IF('👾 RAW MAPPING'!$E$19:$E$55<>"", ROW('👾 RAW MAPPING'!$E$19:$E$55)-ROW('👾 RAW MAPPING'!$E$19)+1), ROW(J22)-ROW(J$18)+1)), "")} | L22: {=IFERROR(INDEX('👾 RAW MAPPING'!$G$19:$G$55, SMALL(IF('👾 RAW MAPPING'!$G$19:$G$55<>"", ROW('👾 RAW MAPPING'!$G$19:$G$55)-ROW('👾 RAW MAPPING'!$G$19)+1), ROW(L22)-ROW(L$18)+1)), "")} | N22: {=IFERROR(INDEX('👾 RAW MAPPING'!$I$19:$I$55, SMALL(IF('👾 RAW MAPPING'!$I$19:$I$55<>"", ROW('👾 RAW MAPPING'!$I$19:$I$55)-ROW('👾 RAW MAPPING'!$I$19)+1), ROW(N22)-ROW(N$18)+1)), "")}
F23: {=IFERROR(INDEX('👾 RAW MAPPING'!$A$19:$A$55, SMALL(IF('👾 RAW MAPPING'!$A$19:$A$55<>"", ROW('👾 RAW MAPPING'!$A$19:$A$55)-ROW('👾 RAW MAPPING'!$A$19)+1), ROW(F23)-ROW(F$18)+1)), "")} | H23: {=IFERROR(INDEX('👾 RAW MAPPING'!$C$19:$C$55, SMALL(IF('👾 RAW MAPPING'!$C$19:$C$55<>"", ROW('👾 RAW MAPPING'!$C$19:$C$55)-ROW('👾 RAW MAPPING'!$C$19)+1), ROW(H23)-ROW(H$18)+1)), "")} | J23: {=IFERROR(INDEX('👾 RAW MAPPING'!$E$19:$E$55, SMALL(IF('👾 RAW MAPPING'!$E$19:$E$55<>"", ROW('👾 RAW MAPPING'!$E$19:$E$55)-ROW('👾 RAW MAPPING'!$E$19)+1), ROW(J23)-ROW(J$18)+1)), "")} | L23: {=IFERROR(INDEX('👾 RAW MAPPING'!$G$19:$G$55, SMALL(IF('👾 RAW MAPPING'!$G$19:$G$55<>"", ROW('👾 RAW MAPPING'!$G$19:$G$55)-ROW('👾 RAW MAPPING'!$G$19)+1), ROW(L23)-ROW(L$18)+1)), "")} | N23: {=IFERROR(INDEX('👾 RAW MAPPING'!$I$19:$I$55, SMALL(IF('👾 RAW MAPPING'!$I$19:$I$55<>"", ROW('👾 RAW MAPPING'!$I$19:$I$55)-ROW('👾 RAW MAPPING'!$I$19)+1), ROW(N23)-ROW(N$18)+1)), "")}
F24: {=IFERROR(INDEX('👾 RAW MAPPING'!$A$19:$A$55, SMALL(IF('👾 RAW MAPPING'!$A$19:$A$55<>"", ROW('👾 RAW MAPPING'!$A$19:$A$55)-ROW('👾 RAW MAPPING'!$A$19)+1), ROW(F24)-ROW(F$18)+1)), "")} | H24: {=IFERROR(INDEX('👾 RAW MAPPING'!$C$19:$C$55, SMALL(IF('👾 RAW MAPPING'!$C$19:$C$55<>"", ROW('👾 RAW MAPPING'!$C$19:$C$55)-ROW('👾 RAW MAPPING'!$C$19)+1), ROW(H24)-ROW(H$18)+1)), "")} | J24: {=IFERROR(INDEX('👾 RAW MAPPING'!$E$19:$E$55, SMALL(IF('👾 RAW MAPPING'!$E$19:$E$55<>"", ROW('👾 RAW MAPPING'!$E$19:$E$55)-ROW('👾 RAW MAPPING'!$E$19)+1), ROW(J24)-ROW(J$18)+1)), "")} | L24: {=IFERROR(INDEX('👾 RAW MAPPING'!$G$19:$G$55, SMALL(IF('👾 RAW MAPPING'!$G$19:$G$55<>"", ROW('👾 RAW MAPPING'!$G$19:$G$55)-ROW('👾 RAW MAPPING'!$G$19)+1), ROW(L24)-ROW(L$18)+1)), "")} | N24: {=IFERROR(INDEX('👾 RAW MAPPING'!$I$19:$I$55, SMALL(IF('👾 RAW MAPPING'!$I$19:$I$55<>"", ROW('👾 RAW MAPPING'!$I$19:$I$55)-ROW('👾 RAW MAPPING'!$I$19)+1), ROW(N24)-ROW(N$18)+1)), "")}
F25: {=IFERROR(INDEX('👾 RAW MAPPING'!$A$19:$A$55, SMALL(IF('👾 RAW MAPPING'!$A$19:$A$55<>"", ROW('👾 RAW MAPPING'!$A$19:$A$55)-ROW('👾 RAW MAPPING'!$A$19)+1), ROW(F25)-ROW(F$18)+1)), "")} | H25: {=IFERROR(INDEX('👾 RAW MAPPING'!$C$19:$C$55, SMALL(IF('👾 RAW MAPPING'!$C$19:$C$55<>"", ROW('👾 RAW MAPPING'!$C$19:$C$55)-ROW('👾 RAW MAPPING'!$C$19)+1), ROW(H25)-ROW(H$18)+1)), "")} | J25: {=IFERROR(INDEX('👾 RAW MAPPING'!$E$19:$E$55, SMALL(IF('👾 RAW MAPPING'!$E$19:$E$55<>"", ROW('👾 RAW MAPPING'!$E$19:$E$55)-ROW('👾 RAW MAPPING'!$E$19)+1), ROW(J25)-ROW(J$18)+1)), "")} | L25: {=IFERROR(INDEX('👾 RAW MAPPING'!$G$19:$G$55, SMALL(IF('👾 RAW MAPPING'!$G$19:$G$55<>"", ROW('👾 RAW MAPPING'!$G$19:$G$55)-ROW('👾 RAW MAPPING'!$G$19)+1), ROW(L25)-ROW(L$18)+1)), "")} | N25: {=IFERROR(INDEX('👾 RAW MAPPING'!$I$19:$I$55, SMALL(IF('👾 RAW MAPPING'!$I$19:$I$55<>"", ROW('👾 RAW MAPPING'!$I$19:$I$55)-ROW('👾 RAW MAPPING'!$I$19)+1), ROW(N25)-ROW(N$18)+1)), "")}
F26: {=IFERROR(INDEX('👾 RAW MAPPING'!$A$19:$A$55, SMALL(IF('👾 RAW MAPPING'!$A$19:$A$55<>"", ROW('👾 RAW MAPPING'!$A$19:$A$55)-ROW('👾 RAW MAPPING'!$A$19)+1), ROW(F26)-ROW(F$18)+1)), "")} | H26: {=IFERROR(INDEX('👾 RAW MAPPING'!$C$19:$C$55, SMALL(IF('👾 RAW MAPPING'!$C$19:$C$55<>"", ROW('👾 RAW MAPPING'!$C$19:$C$55)-ROW('👾 RAW MAPPING'!$C$19)+1), ROW(H26)-ROW(H$18)+1)), "")} | J26: {=IFERROR(INDEX('👾 RAW MAPPING'!$E$19:$E$55, SMALL(IF('👾 RAW MAPPING'!$E$19:$E$55<>"", ROW('👾 RAW MAPPING'!$E$19:$E$55)-ROW('👾 RAW MAPPING'!$E$19)+1), ROW(J26)-ROW(J$18)+1)), "")} | L26: {=IFERROR(INDEX('👾 RAW MAPPING'!$G$19:$G$55, SMALL(IF('👾 RAW MAPPING'!$G$19:$G$55<>"", ROW('👾 RAW MAPPING'!$G$19:$G$55)-ROW('👾 RAW MAPPING'!$G$19)+1), ROW(L26)-ROW(L$18)+1)), "")} | N26: {=IFERROR(INDEX('👾 RAW MAPPING'!$I$19:$I$55, SMALL(IF('👾 RAW MAPPING'!$I$19:$I$55<>"", ROW('👾 RAW MAPPING'!$I$19:$I$55)-ROW('👾 RAW MAPPING'!$I$19)+1), ROW(N26)-ROW(N$18)+1)), "")}
F27: {=IFERROR(INDEX('👾 RAW MAPPING'!$A$19:$A$55, SMALL(IF('👾 RAW MAPPING'!$A$19:$A$55<>"", ROW('👾 RAW MAPPING'!$A$19:$A$55)-ROW('👾 RAW MAPPING'!$A$19)+1), ROW(F27)-ROW(F$18)+1)), "")} | H27: {=IFERROR(INDEX('👾 RAW MAPPING'!$C$19:$C$55, SMALL(IF('👾 RAW MAPPING'!$C$19:$C$55<>"", ROW('👾 RAW MAPPING'!$C$19:$C$55)-ROW('👾 RAW MAPPING'!$C$19)+1), ROW(H27)-ROW(H$18)+1)), "")} | J27: {=IFERROR(INDEX('👾 RAW MAPPING'!$E$19:$E$55, SMALL(IF('👾 RAW MAPPING'!$E$19:$E$55<>"", ROW('👾 RAW MAPPING'!$E$19:$E$55)-ROW('👾 RAW MAPPING'!$E$19)+1), ROW(J27)-ROW(J$18)+1)), "")} | L27: {=IFERROR(INDEX('👾 RAW MAPPING'!$G$19:$G$55, SMALL(IF('👾 RAW MAPPING'!$G$19:$G$55<>"", ROW('👾 RAW MAPPING'!$G$19:$G$55)-ROW('👾 RAW MAPPING'!$G$19)+1), ROW(L27)-ROW(L$18)+1)), "")} | N27: {=IFERROR(INDEX('👾 RAW MAPPING'!$I$19:$I$55, SMALL(IF('👾 RAW MAPPING'!$I$19:$I$55<>"", ROW('👾 RAW MAPPING'!$I$19:$I$55)-ROW('👾 RAW MAPPING'!$I$19)+1), ROW(N27)-ROW(N$18)+1)), "")}
F28: {=IFERROR(INDEX('👾 RAW MAPPING'!$A$19:$A$55, SMALL(IF('👾 RAW MAPPING'!$A$19:$A$55<>"", ROW('👾 RAW MAPPING'!$A$19:$A$55)-ROW('👾 RAW MAPPING'!$A$19)+1), ROW(F28)-ROW(F$18)+1)), "")} | H28: {=IFERROR(INDEX('👾 RAW MAPPING'!$C$19:$C$55, SMALL(IF('👾 RAW MAPPING'!$C$19:$C$55<>"", ROW('👾 RAW MAPPING'!$C$19:$C$55)-ROW('👾 RAW MAPPING'!$C$19)+1), ROW(H28)-ROW(H$18)+1)), "")} | J28: {=IFERROR(INDEX('👾 RAW MAPPING'!$E$19:$E$55, SMALL(IF('👾 RAW MAPPING'!$E$19:$E$55<>"", ROW('👾 RAW MAPPING'!$E$19:$E$55)-ROW('👾 RAW MAPPING'!$E$19)+1), ROW(J28)-ROW(J$18)+1)), "")} | L28: {=IFERROR(INDEX('👾 RAW MAPPING'!$G$19:$G$55, SMALL(IF('👾 RAW MAPPING'!$G$19:$G$55<>"", ROW('👾 RAW MAPPING'!$G$19:$G$55)-ROW('👾 RAW MAPPING'!$G$19)+1), ROW(L28)-ROW(L$18)+1)), "")} | N28: {=IFERROR(INDEX('👾 RAW MAPPING'!$I$19:$I$55, SMALL(IF('👾 RAW MAPPING'!$I$19:$I$55<>"", ROW('👾 RAW MAPPING'!$I$19:$I$55)-ROW('👾 RAW MAPPING'!$I$19)+1), ROW(N28)-ROW(N$18)+1)), "")}
F29: {=IFERROR(INDEX('👾 RAW MAPPING'!$A$19:$A$55, SMALL(IF('👾 RAW MAPPING'!$A$19:$A$55<>"", ROW('👾 RAW MAPPING'!$A$19:$A$55)-ROW('👾 RAW MAPPING'!$A$19)+1), ROW(F29)-ROW(F$18)+1)), "")} | H29: {=IFERROR(INDEX('👾 RAW MAPPING'!$C$19:$C$55, SMALL(IF('👾 RAW MAPPING'!$C$19:$C$55<>"", ROW('👾 RAW MAPPING'!$C$19:$C$55)-ROW('👾 RAW MAPPING'!$C$19)+1), ROW(H29)-ROW(H$18)+1)), "")} | J29: {=IFERROR(INDEX('👾 RAW MAPPING'!$E$19:$E$55, SMALL(IF('👾 RAW MAPPING'!$E$19:$E$55<>"", ROW('👾 RAW MAPPING'!$E$19:$E$55)-ROW('👾 RAW MAPPING'!$E$19)+1), ROW(J29)-ROW(J$18)+1)), "")} | L29: {=IFERROR(INDEX('👾 RAW MAPPING'!$G$19:$G$55, SMALL(IF('👾 RAW MAPPING'!$G$19:$G$55<>"", ROW('👾 RAW MAPPING'!$G$19:$G$55)-ROW('👾 RAW MAPPING'!$G$19)+1), ROW(L29)-ROW(L$18)+1)), "")} | N29: {=IFERROR(INDEX('👾 RAW MAPPING'!$I$19:$I$55, SMALL(IF('👾 RAW MAPPING'!$I$19:$I$55<>"", ROW('👾 RAW MAPPING'!$I$19:$I$55)-ROW('👾 RAW MAPPING'!$I$19)+1), ROW(N29)-ROW(N$18)+1)), "")}
F30: {=IFERROR(INDEX('👾 RAW MAPPING'!$A$19:$A$55, SMALL(IF('👾 RAW MAPPING'!$A$19:$A$55<>"", ROW('👾 RAW MAPPING'!$A$19:$A$55)-ROW('👾 RAW MAPPING'!$A$19)+1), ROW(F30)-ROW(F$18)+1)), "")} | H30: {=IFERROR(INDEX('👾 RAW MAPPING'!$C$19:$C$55, SMALL(IF('👾 RAW MAPPING'!$C$19:$C$55<>"", ROW('👾 RAW MAPPING'!$C$19:$C$55)-ROW('👾 RAW MAPPING'!$C$19)+1), ROW(H30)-ROW(H$18)+1)), "")} | J30: {=IFERROR(INDEX('👾 RAW MAPPING'!$E$19:$E$55, SMALL(IF('👾 RAW MAPPING'!$E$19:$E$55<>"", ROW('👾 RAW MAPPING'!$E$19:$E$55)-ROW('👾 RAW MAPPING'!$E$19)+1), ROW(J30)-ROW(J$18)+1)), "")} | L30: {=IFERROR(INDEX('👾 RAW MAPPING'!$G$19:$G$55, SMALL(IF('👾 RAW MAPPING'!$G$19:$G$55<>"", ROW('👾 RAW MAPPING'!$G$19:$G$55)-ROW('👾 RAW MAPPING'!$G$19)+1), ROW(L30)-ROW(L$18)+1)), "")} | N30: {=IFERROR(INDEX('👾 RAW MAPPING'!$I$19:$I$55, SMALL(IF('👾 RAW MAPPING'!$I$19:$I$55<>"", ROW('👾 RAW MAPPING'!$I$19:$I$55)-ROW('👾 RAW MAPPING'!$I$19)+1), ROW(N30)-ROW(N$18)+1)), "")}
... F36: {=IFERROR(INDEX('👾 RAW MAPPING'!$A$19:$A$55, SMALL(IF('👾 RAW MAPPING'!$A$19:$A$55<>"", ROW('👾 RAW MAPPING'!$A$19:$A$55)-ROW('👾 RAW MAPPING'!$A$19)+1), ROW(F36)-ROW(F$18)+1)), "")} | H36: {=IFERROR(INDEX('👾 RAW MAPPING'!$C$19:$C$55, SMALL(IF('👾 RAW MAPPING'!$C$19:$C$55<>"", ROW('👾 RAW MAPPING'!$C$19:$C$55)-ROW('👾 RAW MAPPING'!$C$19)+1), ROW(H36)-ROW(H$18)+1)), "")} | J36: {=IFERROR(INDEX('👾 RAW MAPPING'!$E$19:$E$55, SMALL(IF('👾 RAW MAPPING'!$E$19:$E$55<>"", ROW('👾 RAW MAPPING'!$E$19:$E$55)-ROW('👾 RAW MAPPING'!$E$19)+1), ROW(J36)-ROW(J$18)+1)), "")} | L36: {=IFERROR(INDEX('👾 RAW MAPPING'!$G$19:$G$55, SMALL(IF('👾 RAW MAPPING'!$G$19:$G$55<>"", ROW('👾 RAW MAPPING'!$G$19:$G$55)-ROW('👾 RAW MAPPING'!$G$19)+1), ROW(L36)-ROW(L$18)+1)), "")} | N36: {=IFERROR(INDEX('👾 RAW MAPPING'!$I$19:$I$55, SMALL(IF('👾 RAW MAPPING'!$I$19:$I$55<>"", ROW('👾 RAW MAPPING'!$I$19:$I$55)-ROW('👾 RAW MAPPING'!$I$19)+1), ROW(N36)-ROW(N$18)+1)), "")}
D37: Reimbursements allowed? | F37: ='🚀 Mobility program(s)'!M112 | H37: ='🚀 Mobility program(s)'!M206 | J37: ='🚀 Mobility program(s)'!M300 | L37: ='🚀 Mobility program(s)'!M394 | N37: ='🚀 Mobility program(s)'!M488
D38: Proof is checked by? | F38: ='🚀 Mobility program(s)'!M113 | H38: ='🚀 Mobility program(s)'!M207 | J38: ='🚀 Mobility program(s)'!M301 | L38: ='🚀 Mobility program(s)'!M395 | N38: ='🚀 Mobility program(s)'!M489
D39: Additional comments per program? | F39: ='🚀 Mobility program(s)'!E115 | H39: ='🚀 Mobility program(s)'!E209 | J39: ='🚀 Mobility program(s)'!E303 | L39: ='🚀 Mobility program(s)'!E397 | N39: ='🚀 Mobility program(s)'!E491
F47: Updated controller rules (these overrule the above mentioned control rules) | O47: Date stamp
D48: Additional comments of CSM | O48: =IF(ISBLANK(F48), "", IF(O48="", NOW(), IF(F48<>F48, NOW(), O48)))
O49: =IF(ISBLANK(F49), "", IF(O49="", NOW(), IF(F49<>F49, NOW(), O49)))
O50: =IF(ISBLANK(F50), "", IF(O50="", NOW(), IF(F50<>F50, NOW(), O50)))
O51: =IF(ISBLANK(F51), "", IF(O51="", NOW(), IF(F51<>F51, NOW(), O51)))
O52: =IF(ISBLANK(F52), "", IF(O52="", NOW(), IF(F52<>F52, NOW(), O52)))
O53: =IF(ISBLANK(F53), "", IF(O53="", NOW(), IF(F53<>F53, NOW(), O53)))

Sheet 👥 Admin creation file
A1: first_name | B1: last_name | C1: email | D1: phone_number | E1: phone_number_country_code | F1: language | G1: gender | H1: date_of_birth | I1: place_of_birth | J1: country_of_birth | K1: nationality | L1: job_title | M1: role | N1: start_on | O1: address__street | P1: address__postal_code | Q1: address__city | R1: address__country_code | S1: new_gen | T1: group_name | U1: invite_on | V1: use_physical_card | W1: internal_payroll_id | X1: cost_center
A2: {=IFERROR(INDEX('👾 RAW MAPPING'!$A$59:$A$73, SMALL(IF('👾 RAW MAPPING'!$A$59:$A$73<>"", ROW('👾 RAW MAPPING'!$A$59:$A$73)-ROW('👾 RAW MAPPING'!$A$59)+1), ROW(A2)-ROW(A$2)+1)), "")} | B2: {=IFERROR(INDEX('👾 RAW MAPPING'!$B$59:$B$73, SMALL(IF('👾 RAW MAPPING'!$B$59:$B$73<>"", ROW('👾 RAW MAPPING'!$B$59:$B$73)-ROW('👾 RAW MAPPING'!$B$59)+1), ROW(B2)-ROW(B$2)+1)), "")} | C2: {=IFERROR(INDEX('👾 RAW MAPPING'!$C$59:$C$73, SMALL(IF('👾 RAW MAPPING'!$C$59:$C$73<>"", ROW('👾 RAW MAPPING'!$C$59:$C$73)-ROW('👾 RAW MAPPING'!$C$59)+1), ROW(C2)-ROW(C$2)+1)), "")} | F2: {=IFERROR(INDEX('👾 RAW MAPPING'!$F$59:$F$73, SMALL(IF('👾 RAW MAPPING'!$F$59:$F$73<>"", ROW('👾 RAW MAPPING'!$F$59:$F$73)-ROW('👾 RAW MAPPING'!$F$59)+1), ROW(F2)-ROW(F$2)+1)), "")} | G2: {=IFERROR(INDEX('👾 RAW MAPPING'!$G$59:$G$73, SMALL(IF('👾 RAW MAPPING'!$G$59:$G$73<>"", ROW('👾 RAW MAPPING'!$G$59:$G$73)-ROW('👾 RAW MAPPING'!$G$59)+1), ROW(G2)-ROW(G$2)+1)), "")} | M2: {=IFERROR(INDEX('👾 RAW MAPPING'!$M$59:$M$73, SMALL(IF('👾 RAW MAPPING'!$M$59:$M$73<>"", ROW('👾 RAW MAPPING'!$M$59:$M$73)-ROW('👾 RAW MAPPING'!$M$59)+1), ROW(M2)-ROW(M$2)+1)), "")} | N2: =IF(A2<>"",TODAY(),"") | S2: =IF(A2<>"","yes","") | U2: =IF(A2<>"",TODAY(),"")
A3: {=IFERROR(INDEX('👾 RAW MAPPING'!$A$59:$A$73, SMALL(IF('👾 RAW MAPPING'!$A$59:$A$73<>"", ROW('👾 RAW MAPPING'!$A$59:$A$73)-ROW('👾 RAW MAPPING'!$A$59)+1), ROW(A3)-ROW(A$2)+1)), "")} | B3: {=IFERROR(INDEX('👾 RAW MAPPING'!$B$59:$B$73, SMALL(IF('👾 RAW MAPPING'!$B$59:$B$73<>"", ROW('👾 RAW MAPPING'!$B$59:$B$73)-ROW('👾 RAW MAPPING'!$B$59)+1), ROW(B3)-ROW(B$2)+1)), "")} | C3: {=IFERROR(INDEX('👾 RAW MAPPING'!$C$59:$C$73, SMALL(IF('👾 RAW MAPPING'!$C$59:$C$73<>"", ROW('👾 RAW MAPPING'!$C$59:$C$73)-ROW('👾 RAW MAPPING'!$C$59)+1), ROW(C3)-ROW(C$2)+1)), "")} | F3: {=IFERROR(INDEX('👾 RAW MAPPING'!$F$59:$F$73, SMALL(IF('👾 RAW MAPPING'!$F$59:$F$73<>"", ROW('👾 RAW MAPPING'!$F$59:$F$73)-ROW('👾 RAW MAPPING'!$F$59)+1), ROW(F3)-ROW(F$2)+1)), "")} | G3: {=IFERROR(INDEX('👾 RAW MAPPING'!$G$59:$G$73, SMALL(IF('👾 RAW MAPPING'!$G$59:$G$73<>"", ROW('👾 RAW MAPPING'!$G$59:$G$73)-ROW('👾 RAW MAPPING'!$G$59)+1), ROW(G3)-ROW(G$2)+1)), "")} | M3: {=IFERROR(INDEX('👾 RAW MAPPING'!$M$59:$M$73, SMALL(IF('👾 RAW MAPPING'!$M$59:$M$73<>"", ROW('👾 RAW MAPPING'!$M$59:$M$73)-ROW('👾 RAW MAPPING'!$M$59)+1), ROW(M3)-ROW(M$2)+1)), "")} | N3: =IF(A3<>"",TODAY(),"") | S3: =IF(A3<>"","yes","") | U3: =IF(A3<>"",TODAY(),"")
A4: {=IFERROR(INDEX('👾 RAW MAPPING'!$A$59:$A$73, SMALL(IF('👾 RAW MAPPING'!$A$59:$A$73<>"", ROW('👾 RAW MAPPING'!$A$59:$A$73)-ROW('👾 RAW MAPPING'!$A$59)+1), ROW(A4)-ROW(A$2)+1)), "")} | B4: {=IFERROR(INDEX('👾 RAW MAPPING'!$B$59:$B$73, SMALL(IF('👾 RAW MAPPING'!$B$59:$B$73<>"", ROW('👾 RAW MAPPING'!$B$59:$B$73)-ROW('👾 RAW MAPPING'!$B$59)+1), ROW(B4)-ROW(B$2)+1)), "")} | C4: {=IFERROR(INDEX('👾 RAW MAPPING'!$C$59:$C$73, SMALL(IF('👾 RAW MAPPING'!$C$59:$C$73<>"", ROW('👾 RAW MAPPING'!$C$59:$C$73)-ROW('👾 RAW MAPPING'!$C$59)+1), ROW(C4)-ROW(C$2)+1)), "")} | F4: {=IFERROR(INDEX('👾 RAW MAPPING'!$F$59:$F$73, SMALL(IF('👾 RAW MAPPING'!$F$59:$F$73<>"", ROW('👾 RAW MAPPING'!$F$59:$F$73)-ROW('👾 RAW MAPPING'!$F$59)+1), ROW(F4)-ROW(F$2)+1)), "")} | G4: {=IFERROR(INDEX('👾 RAW MAPPING'!$G$59:$G$73, SMALL(IF('👾 RAW MAPPING'!$G$59:$G$73<>"", ROW('👾 RAW MAPPING'!$G$59:$G$73)-ROW('👾 RAW MAPPING'!$G$59)+1), ROW(G4)-ROW(G$2)+1)), "")} | M4: {=IFERROR(INDEX('👾 RAW MAPPING'!$M$59:$M$73, SMALL(IF('👾 RAW MAPPING'!$M$59:$M$73<>"", ROW('👾 RAW MAPPING'!$M$59:$M$73)-ROW('👾 RAW MAPPING'!$M$59)+1), ROW(M4)-ROW(M$2)+1)), "")} | N4: =IF(A4<>"",TODAY(),"") | S4: =IF(A4<>"","yes","") | U4: =IF(A4<>"",TODAY(),"")
A5: {=IFERROR(INDEX('👾 RAW MAPPING'!$A$59:$A$73, SMALL(IF('👾 RAW MAPPING'!$A$59:$A$73<>"", ROW('👾 RAW MAPPING'!$A$59:$A$73)-ROW('👾 RAW MAPPING'!$A$59)+1), ROW(A5)-ROW(A$2)+1)), "")} | B5: {=IFERROR(INDEX('👾 RAW MAPPING'!$B$59:$B$73, SMALL(IF('👾 RAW MAPPING'!$B$59:$B$73<>"", ROW('👾 RAW MAPPING'!$B$59:$B$73)-ROW('👾 RAW MAPPING'!$B$59)+1), ROW(B5)-ROW(B$2)+1)), "")} | C5: {=IFERROR(INDEX('👾 RAW MAPPING'!$C$59:$C$73, SMALL(IF('👾 RAW MAPPING'!$C$59:$C$73<>"", ROW('👾 RAW MAPPING'!$C$59:$C$73)-ROW('👾 RAW MAPPING'!$C$59)+1), ROW(C5)-ROW(C$2)+1)), "")} | F5: {=IFERROR(INDEX('👾 RAW MAPPING'!$F$59:$F$73, SMALL(IF('👾 RAW MAPPING'!$F$59:$F$73<>"", ROW('👾 RAW MAPPING'!$F$59:$F$73)-ROW('👾 RAW MAPPING'!$F$59)+1), ROW(F5)-ROW(F$2)+1)), "")} | G5: {=IFERROR(INDEX('👾 RAW MAPPING'!$G$59:$G$73, SMALL(IF('👾 RAW MAPPING'!$G$59:$G$73<>"", ROW('👾 RAW MAPPING'!$G$59:$G$73)-ROW('👾 RAW MAPPING'!$G$59)+1), ROW(G5)-ROW(G$2)+1)), "")} | M5: {=IFERROR(INDEX('👾 RAW MAPPING'!$M$59:$M$73, SMALL(IF('👾 RAW MAPPING'!$M$59:$M$73<>"", ROW('👾 RAW MAPPING'!$M$59:$M$73)-ROW('👾 RAW MAPPING'!$M$59)+1), ROW(M5)-ROW(M$2)+1)), "")} | N5: =IF(A5<>"",TODAY(),"") | S5: =IF(A5<>"","yes","") | U5: =IF(A5<>"",TODAY(),"")
A6: {=IFERROR(INDEX('👾 RAW MAPPING'!$A$59:$A$73, SMALL(IF('👾 RAW MAPPING'!$A$59:$A$73<>"", ROW('👾 RAW MAPPING'!$A$59:$A$73)-ROW('👾 RAW MAPPING'!$A$59)+1), ROW(A6)-ROW(A$2)+1)), "")} | B6: {=IFERROR(INDEX('👾 RAW MAPPING'!$B$59:$B$73, SMALL(IF('👾 RAW MAPPING'!$B$59:$B$73<>"", ROW('👾 RAW MAPPING'!$B$59:$B$73)-ROW('👾 RAW MAPPING'!$B$59)+1), ROW(B6)-ROW(B$2)+1)), "")} | C6: {=IFERROR(INDEX('👾 RAW MAPPING'!$C$59:$C$73, SMALL(IF('👾 RAW MAPPING'!$C$59:$C$73<>"", ROW('👾 RAW MAPPING'!$C$59:$C$73)-ROW('👾 RAW MAPPING'!$C$59)+1), ROW(C6)-ROW(C$2)+1)), "")} | F6: {=IFERROR(INDEX('👾 RAW MAPPING'!$F$59:$F$73, SMALL(IF('👾 RAW MAPPING'!$F$59:$F$73<>"", ROW('👾 RAW MAPPING'!$F$59:$F$73)-ROW('👾 RAW MAPPING'!$F$59)+1), ROW(F6)-ROW(F$2)+1)), "")} | G6: {=IFERROR(INDEX('👾 RAW MAPPING'!$G$59:$G$73, SMALL(IF('👾 RAW MAPPING'!$G$59:$G$73<>"", ROW('👾 RAW MAPPING'!$G$59:$G$73)-ROW('👾 RAW MAPPING'!$G$59)+1), ROW(G6)-ROW(G$2)+1)), "")} | M6: {=IFERROR(INDEX('👾 RAW MAPPING'!$M$59:$M$73, SMALL(IF('👾 RAW MAPPING'!$M$59:$M$73<>"", ROW('👾 RAW MAPPING'!$M$59:$M$73)-ROW('👾 RAW MAPPING'!$M$59)+1), ROW(M6)-ROW(M$2)+1)), "")} | N6: =IF(A6<>"",TODAY(),"") | S6: =IF(A6<>"","yes","") | U6: =IF(A6<>"",TODAY(),"")
A7: {=IFERROR(INDEX('👾 RAW MAPPING'!$A$59:$A$73, SMALL(IF('👾 RAW MAPPING'!$A$59:$A$73<>"", ROW('👾 RAW MAPPING'!$A$59:$A$73)-ROW('👾 RAW MAPPING'!$A$59)+1), ROW(A7)-ROW(A$2)+1)), "")} | B7: {=IFERROR(INDEX('👾 RAW MAPPING'!$B$59:$B$73, SMALL(IF('👾 RAW MAPPING'!$B$59:$B$73<>"", ROW('👾 RAW MAPPING'!$B$59:$B$73)-ROW('👾 RAW MAPPING'!$B$59)+1), ROW(B7)-ROW(B$2)+1)), "")} | C7: {=IFERROR(INDEX('👾 RAW MAPPING'!$C$59:$C$73, SMALL(IF('👾 RAW MAPPING'!$C$59:$C$73<>"", ROW('👾 RAW MAPPING'!$C$59:$C$73)-ROW('👾 RAW MAPPING'!$C$59)+1), ROW(C7)-ROW(C$2)+1)), "")} | F7: {=IFERROR(INDEX('👾 RAW MAPPING'!$F$59:$F$73, SMALL(IF('👾 RAW MAPPING'!$F$59:$F$73<>"", ROW('👾 RAW MAPPING'!$F$59:$F$73)-ROW('👾 RAW MAPPING'!$F$59)+1), ROW(F7)-ROW(F$2)+1)), "")} | G7: {=IFERROR(INDEX('👾 RAW MAPPING'!$G$59:$G$73, SMALL(IF('👾 RAW MAPPING'!$G$59:$G$73<>"", ROW('👾 RAW MAPPING'!$G$59:$G$73)-ROW('👾 RAW MAPPING'!$G$59)+1), ROW(G7)-ROW(G$2)+1)), "")} | M7: {=IFERROR(INDEX('👾 RAW MAPPING'!$M$59:$M$73, SMALL(IF('👾 RAW MAPPING'!$M$59:$M$73<>"", ROW('👾 RAW MAPPING'!$M$59:$M$73)-ROW('👾 RAW MAPPING'!$M$59)+1), ROW(M7)-ROW(M$2)+1)), "")} | N7: =IF(A7<>"",TODAY(),"") | S7: =IF(A7<>"","yes","") | U7: =IF(A7<>"",TODAY(),"")
A8: {=IFERROR(INDEX('👾 RAW MAPPING'!$A$59:$A$73, SMALL(IF('👾 RAW MAPPING'!$A$59:$A$73<>"", ROW('👾 RAW MAPPING'!$A$59:$A$73)-ROW('👾 RAW MAPPING'!$A$59)+1), ROW(A8)-ROW(A$2)+1)), "")} | B8: {=IFERROR(INDEX('👾 RAW MAPPING'!$B$59:$B$73, SMALL(IF('👾 RAW MAPPING'!$B$59:$B$73<>"", ROW('👾 RAW MAPPING'!$B$59:$B$73)-ROW('👾 RAW MAPPING'!$B$59)+1), ROW(B8)-ROW(B$2)+1)), "")} | C8: {=IFERROR(INDEX('👾 RAW MAPPING'!$C$59:$C$73, SMALL(IF('👾 RAW MAPPING'!$C$59:$C$73<>"", ROW('👾 RAW MAPPING'!$C$59:$C$73)-ROW('👾 RAW MAPPING'!$C$59)+1), ROW(C8)-ROW(C$2)+1)), "")} | F8: {=IFERROR(INDEX('👾 RAW MAPPING'!$F$59:$F$73, SMALL(IF('👾 RAW MAPPING'!$F$59:$F$73<>"", ROW('👾 RAW MAPPING'!$F$59:$F$73)-ROW('👾 RAW MAPPING'!$F$59)+1), ROW(F8)-ROW(F$2)+1)), "")} | G8: {=IFERROR(INDEX('👾 RAW MAPPING'!$G$59:$G$73, SMALL(IF('👾 RAW MAPPING'!$G$59:$G$73<>"", ROW('👾 RAW MAPPING'!$G$59:$G$73)-ROW('👾 RAW MAPPING'!$G$59)+1), ROW(G8)-ROW(G$2)+1)), "")} | M8: {=IFERROR(INDEX('👾 RAW MAPPING'!$M$59:$M$73, SMALL(IF('👾 RAW MAPPING'!$M$59:$M$73<>"", ROW('👾 RAW MAPPING'!$M$59:$M$73)-ROW('👾 RAW MAPPING'!$M$59)+1), ROW(M8)-ROW(M$2)+1)), "")} | N8: =IF(A8<>"",TODAY(),"") | S8: =IF(A8<>"","yes","") | U8: =IF(A8<>"",TODAY(),"")
A9: {=IFERROR(INDEX('👾 RAW MAPPING'!$A$59:$A$73, SMALL(IF('👾 RAW MAPPING'!$A$59:$A$73<>"", ROW('👾 RAW MAPPING'!$A$59:$A$73)-ROW('👾 RAW MAPPING'!$A$59)+1), ROW(A9)-ROW(A$2)+1)), "")} | B9: {=IFERROR(INDEX('👾 RAW MAPPING'!$B$59:$B$73, SMALL(IF('👾 RAW MAPPING'!$B$59:$B$73<>"", ROW('👾 RAW MAPPING'!$B$59:$B$73)-ROW('👾 RAW MAPPING'!$B$59)+1), ROW(B9)-ROW(B$2)+1)), "")} | C9: {=IFERROR(INDEX('👾 RAW MAPPING'!$C$59:$C$73, SMALL(IF('👾 RAW MAPPING'!$C$59:$C$73<>"", ROW('👾 RAW MAPPING'!$C$59:$C$73)-ROW('👾 RAW MAPPING'!$C$59)+1), ROW(C9)-ROW(C$2)+1)), "")} | F9: {=IFERROR(INDEX('👾 RAW MAPPING'!$F$59:$F$73, SMALL(IF('👾 RAW MAPPING'!$F$59:$F$73<>"", ROW('👾 RAW MAPPING'!$F$59:$F$73)-ROW('👾 RAW MAPPING'!$F$59)+1), ROW(F9)-ROW(F$2)+1)), "")} | G9: {=IFERROR(INDEX('👾 RAW MAPPING'!$G$59:$G$73, SMALL(IF('👾 RAW MAPPING'!$G$59:$G$73<>"", ROW('👾 RAW MAPPING'!$G$59:$G$73)-ROW('👾 RAW MAPPING'!$G$59)+1), ROW(G9)-ROW(G$2)+1)), "")} | M9: {=IFERROR(INDEX('👾 RAW MAPPING'!$M$59:$M$73, SMALL(IF('👾 RAW MAPPING'!$M$59:$M$73<>"", ROW('👾 RAW MAPPING'!$M$59:$M$73)-ROW('👾 RAW MAPPING'!$M$59)+1), ROW(M9)-ROW(M$2)+1)), "")} | N9: =IF(A9<>"",TODAY(),"") | S9: =IF(A9<>"","yes","") | U9: =IF(A9<>"",TODAY(),"")
A10: {=IFERROR(INDEX('👾 RAW MAPPING'!$A$59:$A$73, SMALL(IF('👾 RAW MAPPING'!$A$59:$A$73<>"", ROW('👾 RAW MAPPING'!$A$59:$A$73)-ROW('👾 RAW MAPPING'!$A$59)+1), ROW(A10)-ROW(A$2)+1)), "")} | B10: {=IFERROR(INDEX('👾 RAW MAPPING'!$B$59:$B$73, SMALL(IF('👾 RAW MAPPING'!$B$59:$B$73<>"", ROW('👾 RAW MAPPING'!$B$59:$B$73)-ROW('👾 RAW MAPPING'!$B$59)+1), ROW(B10)-ROW(B$2)+1)), "")} | C10: {=IFERROR(INDEX('👾 RAW MAPPING'!$C$59:$C$73, SMALL(IF('👾 RAW MAPPING'!$C$59:$C$73<>"", ROW('👾 RAW MAPPING'!$C$59:$C$73)-ROW('👾 RAW MAPPING'!$C$59)+1), ROW(C10)-ROW(C$2)+1)), "")} | F10: {=IFERROR(INDEX('👾 RAW MAPPING'!$F$59:$F$73, SMALL(IF('👾 RAW MAPPING'!$F$59:$F$73<>"", ROW('👾 RAW MAPPING'!$F$59:$F$73)-ROW('👾 RAW MAPPING'!$F$59)+1), ROW(F10)-ROW(F$2)+1)), "")} | G10: {=IFERROR(INDEX('👾 RAW MAPPING'!$G$59:$G$73, SMALL(IF('👾 RAW MAPPING'!$G$59:$G$73<>"", ROW('👾 RAW MAPPING'!$G$59:$G$73)-ROW('👾 RAW MAPPING'!$G$59)+1), ROW(G10)-ROW(G$2)+1)), "")} | M10: {=IFERROR(INDEX('👾 RAW MAPPING'!$M$59:$M$73, SMALL(IF('👾 RAW MAPPING'!$M$59:$M$73<>"", ROW('👾 RAW MAPPING'!$M$59:$M$73)-ROW('👾 RAW MAPPING'!$M$59)+1), ROW(M10)-ROW(M$2)+1)), "")} | N10: =IF(A10<>"",TODAY(),"") | S10: =IF(A10<>"","yes","") | U10: =IF(A10<>"",TODAY(),"")
A11: {=IFERROR(INDEX('👾 RAW MAPPING'!$A$59:$A$73, SMALL(IF('👾 RAW MAPPING'!$A$59:$A$73<>"", ROW('👾 RAW MAPPING'!$A$59:$A$73)-ROW('👾 RAW MAPPING'!$A$59)+1), ROW(A11)-ROW(A$2)+1)), "")} | B11: {=IFERROR(INDEX('👾 RAW MAPPING'!$B$59:$B$73, SMALL(IF('👾 RAW MAPPING'!$B$59:$B$73<>"", ROW('👾 RAW MAPPING'!$B$59:$B$73)-ROW('👾 RAW MAPPING'!$B$59)+1), ROW(B11)-ROW(B$2)+1)), "")} | C11: {=IFERROR(INDEX('👾 RAW MAPPING'!$C$59:$C$73, SMALL(IF('👾 RAW MAPPING'!$C$59:$C$73<>"", ROW('👾 RAW MAPPING'!$C$59:$C$73)-ROW('👾 RAW MAPPING'!$C$59)+1), ROW(C11)-ROW(C$2)+1)), "")} | F11: {=IFERROR(INDEX('👾 RAW MAPPING'!$F$59:$F$73, SMALL(IF('👾 RAW MAPPING'!$F$59:$F$73<>"", ROW('👾 RAW MAPPING'!$F$59:$F$73)-ROW('👾 RAW MAPPING'!$F$59)+1), ROW(F11)-ROW(F$2)+1)), "")} | G11: {=IFERROR(INDEX('👾 RAW MAPPING'!$G$59:$G$73, SMALL(IF('👾 RAW MAPPING'!$G$59:$G$73<>"", ROW('👾 RAW MAPPING'!$G$59:$G$73)-ROW('👾 RAW MAPPING'!$G$59)+1), ROW(G11)-ROW(G$2)+1)), "")} | M11: {=IFERROR(INDEX('👾 RAW MAPPING'!$M$59:$M$73, SMALL(IF('👾 RAW MAPPING'!$M$59:$M$73<>"", ROW('👾 RAW MAPPING'!$M$59:$M$73)-ROW('👾 RAW MAPPING'!$M$59)+1), ROW(M11)-ROW(M$2)+1)), "")} | N11: =IF(A11<>"",TODAY(),"") | S11: =IF(A11<>"","yes","") | U11: =IF(A11<>"",TODAY(),"")
A12: {=IFERROR(INDEX('👾 RAW MAPPING'!$A$59:$A$73, SMALL(IF('👾 RAW MAPPING'!$A$59:$A$73<>"", ROW('👾 RAW MAPPING'!$A$59:$A$73)-ROW('👾 RAW MAPPING'!$A$59)+1), ROW(A12)-ROW(A$2)+1)), "")} | B12: {=IFERROR(INDEX('👾 RAW MAPPING'!$B$59:$B$73, SMALL(IF('👾 RAW MAPPING'!$B$59:$B$73<>"", ROW('👾 RAW MAPPING'!$B$59:$B$73)-ROW('👾 RAW MAPPING'!$B$59)+1), ROW(B12)-ROW(B$2)+1)), "")} | C12: {=IFERROR(INDEX('👾 RAW MAPPING'!$C$59:$C$73, SMALL(IF('👾 RAW MAPPING'!$C$59:$C$73<>"", ROW('👾 RAW MAPPING'!$C$59:$C$73)-ROW('👾 RAW MAPPING'!$C$59)+1), ROW(C12)-ROW(C$2)+1)), "")} | F12: {=IFERROR(INDEX('👾 RAW MAPPING'!$F$59:$F$73, SMALL(IF('👾 RAW MAPPING'!$F$59:$F$73<>"", ROW('👾 RAW MAPPING'!$F$59:$F$73)-ROW('👾 RAW MAPPING'!$F$59)+1), ROW(F12)-ROW(F$2)+1)), "")} | G12: {=IFERROR(INDEX('👾 RAW MAPPING'!$G$59:$G$73, SMALL(IF('👾 RAW MAPPING'!$G$59:$G$73<>"", ROW('👾 RAW MAPPING'!$G$59:$G$73)-ROW('👾 RAW MAPPING'!$G$59)+1), ROW(G12)-ROW(G$2)+1)), "")} | M12: {=IFERROR(INDEX('👾 RAW MAPPING'!$M$59:$M$73, SMALL(IF('👾 RAW MAPPING'!$M$59:$M$73<>"", ROW('👾 RAW MAPPING'!$M$59:$M$73)-ROW('👾 RAW MAPPING'!$M$59)+1), ROW(M12)-ROW(M$2)+1)), "")} | N12: =IF(A12<>"",TODAY(),"") | S12: =IF(A12<>"","yes","") | U12: =IF(A12<>"",TODAY(),"")
A13: {=IFERROR(INDEX('👾 RAW MAPPING'!$A$59:$A$73, SMALL(IF('👾 RAW MAPPING'!$A$59:$A$73<>"", ROW('👾 RAW MAPPING'!$A$59:$A$73)-ROW('👾 RAW MAPPING'!$A$59)+1), ROW(A13)-ROW(A$2)+1)), "")} | B13: {=IFERROR(INDEX('👾 RAW MAPPING'!$B$59:$B$73, SMALL(IF('👾 RAW MAPPING'!$B$59:$B$73<>"", ROW('👾 RAW MAPPING'!$B$59:$B$73)-ROW('👾 RAW MAPPING'!$B$59)+1), ROW(B13)-ROW(B$2)+1)), "")} | C13: {=IFERROR(INDEX('👾 RAW MAPPING'!$C$59:$C$73, SMALL(IF('👾 RAW MAPPING'!$C$59:$C$73<>"", ROW('👾 RAW MAPPING'!$C$59:$C$73)-ROW('👾 RAW MAPPING'!$C$59)+1), ROW(C13)-ROW(C$2)+1)), "")} | F13: {=IFERROR(INDEX('👾 RAW MAPPING'!$F$59:$F$73, SMALL(IF('👾 RAW MAPPING'!$F$59:$F$73<>"", ROW('👾 RAW MAPPING'!$F$59:$F$73)-ROW('👾 RAW MAPPING'!$F$59)+1), ROW(F13)-ROW(F$2)+1)), "")} | G13: {=IFERROR(INDEX('👾 RAW MAPPING'!$G$59:$G$73, SMALL(IF('👾 RAW MAPPING'!$G$59:$G$73<>"", ROW('👾 RAW MAPPING'!$G$59:$G$73)-ROW('👾 RAW MAPPING'!$G$59)+1), ROW(G13)-ROW(G$2)+1)), "")} | M13: {=IFERROR(INDEX('👾 RAW MAPPING'!$M$59:$M$73, SMALL(IF('👾 RAW MAPPING'!$M$59:$M$73<>"", ROW('👾 RAW MAPPING'!$M$59:$M$73)-ROW('👾 RAW MAPPING'!$M$59)+1), ROW(M13)-ROW(M$2)+1)), "")} | N13: =IF(A13<>"",TODAY(),"") | S13: =IF(A13<>"","yes","") | U13: =IF(A13<>"",TODAY(),"")
... A16: {=IFERROR(INDEX('👾 RAW MAPPING'!$A$59:$A$73, SMALL(IF('👾 RAW MAPPING'!$A$59:$A$73<>"", ROW('👾 RAW MAPPING'!$A$59:$A$73)-ROW('👾 RAW MAPPING'!$A$59)+1), ROW(A16)-ROW(A$2)+1)), "")} | B16: {=IFERROR(INDEX('👾 RAW MAPPING'!$B$59:$B$73, SMALL(IF('👾 RAW MAPPING'!$B$59:$B$73<>"", ROW('👾 RAW MAPPING'!$B$59:$B$73)-ROW('👾 RAW MAPPING'!$B$59)+1), ROW(B16)-ROW(B$2)+1)), "")} | C16: {=IFERROR(INDEX('👾 RAW MAPPING'!$C$59:$C$73, SMALL(IF('👾 RAW MAPPING'!$C$59:$C$73<>"", ROW('👾 RAW MAPPING'!$C$59:$C$73)-ROW('👾 RAW MAPPING'!$C$59)+1), ROW(C16)-ROW(C$2)+1)), "")} | F16: {=IFERROR(INDEX('👾 RAW MAPPING'!$F$59:$F$73, SMALL(IF('👾 RAW MAPPING'!$F$59:$F$73<>"", ROW('👾 RAW MAPPING'!$F$59:$F$73)-ROW('👾 RAW MAPPING'!$F$59)+1), ROW(F16)-ROW(F$2)+1)), "")} | G16: {=IFERROR(INDEX('👾 RAW MAPPING'!$G$59:$G$73, SMALL(IF('👾 RAW MAPPING'!$G$59:$G$73<>"", ROW('👾 RAW MAPPING'!$G$59:$G$73)-ROW('👾 RAW MAPPING'!$G$59)+1), ROW(G16)-ROW(G$2)+1)), "")} | M16: {=IFERROR(INDEX('👾 RAW MAPPING'!$M$59:$M$73, SMALL(IF('👾 RAW MAPPING'!$M$59:$M$73<>"", ROW('👾 RAW MAPPING'!$M$59:$M$73)-ROW('👾 RAW MAPPING'!$M$59)+1), ROW(M16)-ROW(M$2)+1)), "")} | N16: =IF(A16<>"",TODAY(),"") | S16: =IF(A16<>"","yes","") | U16: =IF(A16<>"",TODAY(),"")

Sheet 💰 Prepayment notice
B3: Skipr SA/NV
B5: Cantersteen 12
B6: 1000 Brussels
B7: BE0712537551
C8: ACCENTURE OPERATIONS CLIENT SERVICES SA
B10: Prepayment notice | F10: =VLOOKUP(C8,'🤝 Client information'!C80:K89 , 6, FALSE) -> #N/A
F11: =VLOOKUP(C8,'🤝 Client information'!C80:K89 , 9, FALSE) -> #N/A
F12: =VLOOKUP(C8,'🤝 Client information'!C80:K89 , 5, FALSE) -> #N/A
B15: date
B16: =today() -> 46155 | D16: - | E16: -
B18: Description | F18: Amount
B19: Prepayment Mobility Budget | F19: 1
B25: Total hors TVA | F25: =F19 -> 1
B26: TVA | F26: n/a
B27: A payer, TVAc | F27: =F25 -> 1
B31: Your payment account: | F31: =VLOOKUP(C8,'👾 RAW MAPPING'!F6:J15 , 5, FALSE) -> #N/A
B32: BIC: | F32: TRZOFR21

Sheet 👾 RAW MAPPING
A2: 👾 | B2: Raw mapping
A5: Skipr team contacts (sheet client information 3.4) | F5: Entity name | J5: IBAN wallet
A6: Hélène | B6: Marcq | C6: helene@skipr.co | D6: +32499349511 | F6: ='🤝 Client information'!C80 | K6: < To be completed by CSM
A7: Maroussia | B7: Collette | C7: maroussia@skipr.co | D7: +32479433369 | F7: ='🤝 Client information'!C81
A8: Steve | B8: Boutremans | C8: steve.boutremans@skipr.co | F8: ='🤝 Client information'!C82
A9: Maxim | B9: Snyers | C9: maxim@skipr.co | D9: +32474573339 | F9: ='🤝 Client information'!C83
A10: Charlie | B10: Millgate | C10: charlie@skipr.co | D10: +32492729294 | F10: ='🤝 Client information'!C84
A11: Denis | B11: Huberland | C11: denis@skipr.co | D11: +32484555086 | F11: ='🤝 Client information'!C85
A12: Victor | B12: Rembours | C12: victor@skipr.co | D12: +33659612262 | F12: ='🤝 Client information'!C86
A13: Jerome | B13: Dambrain | C13: jerome@skipr.co | D13: +32499640271 | F13: ='🤝 Client information'!C87
A14: Thaïs | B14: Launay | C14: Thais@skipr.co | D14: +33603244564 | F14: ='🤝 Client information'!C88
F15: ='🤝 Client information'!C89
A17: Sum-up of services per program without blanks in between (used in sheet Validation briefing)
A18: Program 1 | B18: Services | C18: Program 2 | D18: Services | E18: Program 3 | F18: Services | G18: Program 4 | H18: Services | I18: Program 5 | J18: Services
